Workbook

Sheet แผนเรียน v13
A1: แผนการเรียน ป.ตรี เศรษฐศาสตร์ ม.รามคำแหง — Quant+Finance/IB (v13: 8 เทอม + 3 Summer)
A2: v13: ย้าย RAM 9 ตัวลง 3 ภาคฤดูร้อน (อย่างละ 3) • RAM1111 คงไว้ปี1/เทอม1 • เพิ่มวิชาสนใจ: STA2016, FIN2202, STA3504, FIN3210 + แนะนำ STA4309 | ★=เพิ่มใหม่ v13 | ยาก/10: เขียว≤4 เหลือง5-6 ส้ม7-8 แดง9-10
A4: ✅ | B4: รหัส | C4: ชื่อวิชา | D4: นก. | E4: ยาก/10 | F4: หมวด / เหตุผล | G4: บุพวิชา | H4: สถานะ / หมายเหตุ
A5: ปีที่ 1 / เทอม 1 (18 นก. • ยากเฉลี่ย 3.3/10) | H5: 18 นก.
B6: ECO1121 | C6: หลักเศรษฐศาสตร์จุลภาค | D6: 3 | E6: 3 | F6: แกน econ | G6: - | H6: ✓
B7: ECO1123 | C7: คณิต–สถิติเบื้องต้นสำหรับ ศ. | D7: 3 | E7: 4 | F7: แกน | G7: - | H7: ✓
B8: ACC1103 | C8: การบัญชีการเงิน | D8: 3 | E8: 4 | F8: แกน econ | G8: - | H8: ✓
B9: MTH1101 | C9: Calculus & Analytic Geometry I | D9: 3 | E9: 4 | F9: เลือกเสรี | G9: - | H9: ✓
B10: RAM1111 | C10: English in Daily Life | D10: 3 | E10: 2 | F10: ศึกษาทั่วไป 1.1 (อังกฤษ บังคับ) | G10: - | H10: ✓ (RAM ตัวที่คงไว้)
B11: COS1101 | C11: Introduction to Computer Science | D11: 3 | E11: 3 | F11: เก็บเพิ่ม • พื้นฐาน CS | G11: - | H11: ✓
A12: ปีที่ 1 / เทอม 2 (18 นก. • ยากเฉลี่ย 4.8/10) | H12: 18 นก.
B13: ECO1122 | C13: หลักเศรษฐศาสตร์มหภาค | D13: 3 | E13: 3 | F13: แกน econ | G13: ECO1123 | H13: ✓
B14: MTH1102 | C14: Calculus & Analytic Geometry II | D14: 3 | E14: 5 | F14: เลือกเสรี | G14: MTH1101 | H14: ✓
B15: MTH2001 | C15: Fundamental Concepts in Math 1 | D15: 3 | E15: 7 | F15: ★ พิสูจน์ | G15: - | H15: ✓
B16: MTH2206 | C16: Matrix Theory & Linear Algebra 1 | D16: 3 | E16: 5 | F16: โทคณิต | G16: MTH1101 | H16: ✓
B17: COS1103 | C17: Algorithms and Programming | D17: 3 | E17: 5 | F17: เก็บเพิ่ม • coding | G17: COS1101 | H17: ✓ (CR COS1101)
B18: STA2016 | C18: Business Statistics & Quant Analysis | D18: 3 | E18: 4 | F18: ★ เพิ่ม v13 • สถิติธุรกิจ | G18: (เช็กภาควิชา) | H18: ✓ intro
A19: ☀ ภาคฤดูร้อน ปี 1 (9 นก. • ยากเฉลี่ย 2.0/10) | H19: 9 นก.
B20: RAM1103 | C20: Thai for Communication at Work | D20: 3 | E20: 2 | F20: ศึกษาทั่วไป 1.1 (ไทย) | G20: - | H20: ✓
B21: RAM1131 | C21: Digital Literacy | D21: 3 | E21: 2 | F21: ศึกษาทั่วไป 1.1 (เทคโนโลยี) | G21: - | H21: ✓
B22: RAM1301 | C22: คุณธรรมคู่ความรู้ | D22: 3 | E22: 2 | F22: ศึกษาทั่วไป 1.3 (พลเมือง บังคับ) | G22: - | H22: ✓
A23: ปีที่ 2 / เทอม 1 (21 นก. • ยากเฉลี่ย 5.6/10) | H23: 21 นก.
B24: ECO2121 | C24: ทฤษฎีจุลภาค 1 | D24: 3 | E24: 6 | F24: แกน econ | G24: ECO1121,1123 | H24: ✓
B25: ECO2122 | C25: ทฤษฎีมหภาค 1 | D25: 3 | E25: 6 | F25: แกน econ | G25: ECO1122,1123 | H25: ✓
B26: ECO2125 | C26: คณิตศาสตร์สำหรับเศรษฐศาสตร์ | D26: 3 | E26: 6 | F26: แกน • สัญญาณ | G26: ECO1123 | H26: ✓
B27: ECO2129 | C27: เศรษฐกิจประเทศไทย | D27: 3 | E27: 3 | F27: แกน econ | G27: ECO1121,1122 | H27: ✓
B28: MTH2103 | C28: Calculus & Analytic Geometry III | D28: 3 | E28: 6 | F28: โทคณิต | G28: MTH1102 | H28: ✓
B29: STA3101 | C29: Probability Theory 1 | D29: 3 | E29: 7 | F29: ★ ความน่าจะเป็น | G29: MTH1102 | H29: ✓
B30: STA2003 | C30: Principles of Statistics | D30: 3 | E30: 5 | F30: บุพวิชาของ ECO2126 & MTH3611 | G30: - | H30: ✓
A31: ปีที่ 2 / เทอม 2 (21 นก. • ยากเฉลี่ย 6.4/10) | H31: 21 นก.
B32: ECO2123 | C32: ทฤษฎีจุลภาค 2 | D32: 3 | E32: 7 | F32: แกน econ | G32: ECO2121 | H32: ✓
B33: ECO2124 | C33: ทฤษฎีมหภาค 2 | D33: 3 | E33: 7 | F33: แกน econ | G33: ECO2122 | H33: ✓
B34: ECO2126 | C34: สถิติสำหรับเศรษฐศาสตร์ | D34: 3 | E34: 6 | F34: แกน • สัญญาณ | G34: STA2003 | H34: ✓
B35: MTH2104 | C35: Advanced Calculus 1 | D35: 3 | E35: 8 | F35: โทคณิต | G35: MTH2103 | H35: ✓
B36: MTH3204 | C36: Matrix Theory & Linear Algebra 2 | D36: 3 | E36: 7 | F36: โทคณิต | G36: MTH2206 | H36: ✓
B37: ACC2202 | C37: Intermediate Accounting | D37: 3 | E37: 6 | F37: บัญชีเชิงลึก | G37: ACC1103 | H37: ⚠️ เช็ก
B38: FIN2202 | C38: Financial Institutions & Markets | D38: 3 | E38: 4 | F38: ★ เพิ่ม v13 • สถาบัน/ตลาดการเงิน | G38: (เช็ก PR) | H38: ⚠️ ข้ามคณะ
A39: ☀ ภาคฤดูร้อน ปี 2 (9 นก. • ยากเฉลี่ย 2.3/10) | H39: 9 นก.
B40: RAM1141 | C40: ศาสตร์แห่งบุคลิกภาพ | D40: 3 | E40: 2 | F40: ศึกษาทั่วไป 1.1 (ปรับตัว) | G40: - | H40: ✓
B41: RAM1204 | C41: Mathematics & Statistics for Daily Life | D41: 3 | E41: 3 | F41: ศึกษาทั่วไป 1.2 (ทักษะคิด) | G41: - | H41: ✓
...

Sheet GPAX
A1: 🎓 คำนวณ GPAX อัตโนมัติ — เลือกเกรดในช่องสีเหลือง
A2: A=4 B+=3.5 B=3 C+=2.5 C=2 D+=1.5 D=1 F=0 • GPAX=Σ(แต้ม×นก.)÷Σนก.ที่มีเกรด • รวม Summer แล้ว
A4: 📊 สรุปผล (คำนวณอัตโนมัติ) | I4: GPA รายเทอม
A5: GPAX สะสม | C5: =IF($G$5=0,"",SUM($G$10:$G$75)/$G$5) | E5: หน่วยกิตที่มีเกรดแล้ว | G5: =SUMPRODUCT(($E$10:$E$75<>"")*$D$10:$D$75) | I5: เทอม | J5: GPA | K5: นก.
A6: เทียบเกียรตินิยม* | C6: =IF($C$5="","-",IF($C$5>=3.8,"อันดับ 1 เหรียญทอง 🥇",IF($C$5>=3.6,"อันดับ 1 🏆",IF($C$5>=3.3,"อันดับ 2 🥈","ไม่เข้าเกณฑ์")))) | E6: หน่วยกิตรวมทั้งหมด | G6: =SUM($D$10:$D$75) | I6: 1/1 | J6: =IF(SUMPRODUCT(($A$10:$A$75=$I6)*($E$10:$E$75<>"")*$D$10:$D$75)=0,"",SUMPRODUCT(($A$10:$A$75=$I6)*$G$10:$G$75)/SUMPRODUCT(($A$10:$A$75=$I6)*($E$10:$E$75<>"")*$D$10:$D$75)) | K6: =SUMPRODUCT(($A$10:$A$75=$I6)*($E$10:$E$75<>"")*$D$10:$D$75)
A7: 🎯 ตั้งเป้า GPAX (กรอก) | C7: 3.8 | E7: ต้องได้เฉลี่ยอีก (เต็ม 4) | G7: =IF(($G$6-$G$5)<=0,"-",IF($C$7="","",($C$7*$G$6-SUM($G$10:$G$75))/($G$6-$G$5))) | I7: 1/2 | J7: =IF(SUMPRODUCT(($A$10:$A$75=$I7)*($E$10:$E$75<>"")*$D$10:$D$75)=0,"",SUMPRODUCT(($A$10:$A$75=$I7)*$G$10:$G$75)/SUMPRODUCT(($A$10:$A$75=$I7)*($E$10:$E$75<>"")*$D$10:$D$75)) | K7: =SUMPRODUCT(($A$10:$A$75=$I7)*($E$10:$E$75<>"")*$D$10:$D$75)
A8: เกณฑ์: เหรียญทอง ≥3.80 | อันดับ1 = 3.60–3.79 | อันดับ2 = 3.30–3.59 • ดูชีต 'เทียบ ป.โท Top-U' | I8: 1/S | J8: =IF(SUMPRODUCT(($A$10:$A$75=$I8)*($E$10:$E$75<>"")*$D$10:$D$75)=0,"",SUMPRODUCT(($A$10:$A$75=$I8)*$G$10:$G$75)/SUMPRODUCT(($A$10:$A$75=$I8)*($E$10:$E$75<>"")*$D$10:$D$75)) | K8: =SUMPRODUCT(($A$10:$A$75=$I8)*($E$10:$E$75<>"")*$D$10:$D$75)
A9: ปี/เทอม | B9: รหัส | C9: ชื่อวิชา | D9: นก. | E9: เกรด | F9: แต้ม | G9: แต้ม×นก. | I9: 2/1 | J9: =IF(SUMPRODUCT(($A$10:$A$75=$I9)*($E$10:$E$75<>"")*$D$10:$D$75)=0,"",SUMPRODUCT(($A$10:$A$75=$I9)*$G$10:$G$75)/SUMPRODUCT(($A$10:$A$75=$I9)*($E$10:$E$75<>"")*$D$10:$D$75)) | K9: =SUMPRODUCT(($A$10:$A$75=$I9)*($E$10:$E$75<>"")*$D$10:$D$75)
A10: 1/1 | B10: ECO1121 | C10: หลักเศรษฐศาสตร์จุลภาค | D10: 3 | F10: =IFERROR(VLOOKUP($E10,Scale!$A$2:$B$9,2,FALSE),"") | G10: =IF($E10="",0,$F10*$D10) | I10: 2/2 | J10: =IF(SUMPRODUCT(($A$10:$A$75=$I10)*($E$10:$E$75<>"")*$D$10:$D$75)=0,"",SUMPRODUCT(($A$10:$A$75=$I10)*$G$10:$G$75)/SUMPRODUCT(($A$10:$A$75=$I10)*($E$10:$E$75<>"")*$D$10:$D$75)) | K10: =SUMPRODUCT(($A$10:$A$75=$I10)*($E$10:$E$75<>"")*$D$10:$D$75)
A11: 1/1 | B11: ECO1123 | C11: คณิต–สถิติเบื้องต้นสำหรับ ศ. | D11: 3 | F11: =IFERROR(VLOOKUP($E11,Scale!$A$2:$B$9,2,FALSE),"") | G11: =IF($E11="",0,$F11*$D11) | I11: 2/S | J11: =IF(SUMPRODUCT(($A$10:$A$75=$I11)*($E$10:$E$75<>"")*$D$10:$D$75)=0,"",SUMPRODUCT(($A$10:$A$75=$I11)*$G$10:$G$75)/SUMPRODUCT(($A$10:$A$75=$I11)*($E$10:$E$75<>"")*$D$10:$D$75)) | K11: =SUMPRODUCT(($A$10:$A$75=$I11)*($E$10:$E$75<>"")*$D$10:$D$75)
A12: 1/1 | B12: ACC1103 | C12: การบัญชีการเงิน | D12: 3 | F12: =IFERROR(VLOOKUP($E12,Scale!$A$2:$B$9,2,FALSE),"") | G12: =IF($E12="",0,$F12*$D12) | I12: 3/1 | J12: =IF(SUMPRODUCT(($A$10:$A$75=$I12)*($E$10:$E$75<>"")*$D$10:$D$75)=0,"",SUMPRODUCT(($A$10:$A$75=$I12)*$G$10:$G$75)/SUMPRODUCT(($A$10:$A$75=$I12)*($E$10:$E$75<>"")*$D$10:$D$75)) | K12: =SUMPRODUCT(($A$10:$A$75=$I12)*($E$10:$E$75<>"")*$D$10:$D$75)
A13: 1/1 | B13: MTH1101 | C13: Calculus & Analytic Geometry I | D13: 3 | F13: =IFERROR(VLOOKUP($E13,Scale!$A$2:$B$9,2,FALSE),"") | G13: =IF($E13="",0,$F13*$D13) | I13: 3/2 | J13: =IF(SUMPRODUCT(($A$10:$A$75=$I13)*($E$10:$E$75<>"")*$D$10:$D$75)=0,"",SUMPRODUCT(($A$10:$A$75=$I13)*$G$10:$G$75)/SUMPRODUCT(($A$10:$A$75=$I13)*($E$10:$E$75<>"")*$D$10:$D$75)) | K13: =SUMPRODUCT(($A$10:$A$75=$I13)*($E$10:$E$75<>"")*$D$10:$D$75)
A14: 1/1 | B14: RAM1111 | C14: English in Daily Life | D14: 3 | F14: =IFERROR(VLOOKUP($E14,Scale!$A$2:$B$9,2,FALSE),"") | G14: =IF($E14="",0,$F14*$D14) | I14: 3/S | J14: =IF(SUMPRODUCT(($A$10:$A$75=$I14)*($E$10:$E$75<>"")*$D$10:$D$75)=0,"",SUMPRODUCT(($A$10:$A$75=$I14)*$G$10:$G$75)/SUMPRODUCT(($A$10:$A$75=$I14)*($E$10:$E$75<>"")*$D$10:$D$75)) | K14: =SUMPRODUCT(($A$10:$A$75=$I14)*($E$10:$E$75<>"")*$D$10:$D$75)
A15: 1/1 | B15: COS1101 | C15: Introduction to Computer Science | D15: 3 | F15: =IFERROR(VLOOKUP($E15,Scale!$A$2:$B$9,2,FALSE),"") | G15: =IF($E15="",0,$F15*$D15) | I15: 4/1 | J15: =IF(SUMPRODUCT(($A$10:$A$75=$I15)*($E$10:$E$75<>"")*$D$10:$D$75)=0,"",SUMPRODUCT(($A$10:$A$75=$I15)*$G$10:$G$75)/SUMPRODUCT(($A$10:$A$75=$I15)*($E$10:$E$75<>"")*$D$10:$D$75)) | K15: =SUMPRODUCT(($A$10:$A$75=$I15)*($E$10:$E$75<>"")*$D$10:$D$75)
A16: 1/2 | B16: ECO1122 | C16: หลักเศรษฐศาสตร์มหภาค | D16: 3 | F16: =IFERROR(VLOOKUP($E16,Scale!$A$2:$B$9,2,FALSE),"") | G16: =IF($E16="",0,$F16*$D16) | I16: 4/2 | J16: =IF(SUMPRODUCT(($A$10:$A$75=$I16)*($E$10:$E$75<>"")*$D$10:$D$75)=0,"",SUMPRODUCT(($A$10:$A$75=$I16)*$G$10:$G$75)/SUMPRODUCT(($A$10:$A$75=$I16)*($E$10:$E$75<>"")*$D$10:$D$75)) | K16: =SUMPRODUCT(($A$10:$A$75=$I16)*($E$10:$E$75<>"")*$D$10:$D$75)
A17: 1/2 | B17: MTH1102 | C17: Calculus & Analytic Geometry II | D17: 3 | F17: =IFERROR(VLOOKUP($E17,Scale!$A$2:$B$9,2,FALSE),"") | G17: =IF($E17="",0,$F17*$D17)
A18: 1/2 | B18: MTH2001 | C18: Fundamental Concepts in Math 1 | D18: 3 | F18: =IFERROR(VLOOKUP($E18,Scale!$A$2:$B$9,2,FALSE),"") | G18: =IF($E18="",0,$F18*$D18)
A19: 1/2 | B19: MTH2206 | C19: Matrix Theory & Linear Algebra 1 | D19: 3 | F19: =IFERROR(VLOOKUP($E19,Scale!$A$2:$B$9,2,FALSE),"") | G19: =IF($E19="",0,$F19*$D19)
A20: 1/2 | B20: COS1103 | C20: Algorithms and Programming | D20: 3 | F20: =IFERROR(VLOOKUP($E20,Scale!$A$2:$B$9,2,FALSE),"") | G20: =IF($E20="",0,$F20*$D20)
A21: 1/2 | B21: STA2016 | C21: Business Statistics & Quant Analysis | D21: 3 | F21: =IFERROR(VLOOKUP($E21,Scale!$A$2:$B$9,2,FALSE),"") | G21: =IF($E21="",0,$F21*$D21)
A22: 1/S | B22: RAM1103 | C22: Thai for Communication at Work | D22: 3 | F22: =IFERROR(VLOOKUP($E22,Scale!$A$2:$B$9,2,FALSE),"") | G22: =IF($E22="",0,$F22*$D22)
A23: 1/S | B23: RAM1131 | C23: Digital Literacy | D23: 3 | F23: =IFERROR(VLOOKUP($E23,Scale!$A$2:$B$9,2,FALSE),"") | G23: =IF($E23="",0,$F23*$D23)
A24: 1/S | B24: RAM1301 | C24: คุณธรรมคู่ความรู้ | D24: 3 | F24: =IFERROR(VLOOKUP($E24,Scale!$A$2:$B$9,2,FALSE),"") | G24: =IF($E24="",0,$F24*$D24)
A25: 2/1 | B25: ECO2121 | C25: ทฤษฎีจุลภาค 1 | D25: 3 | F25: =IFERROR(VLOOKUP($E25,Scale!$A$2:$B$9,2,FALSE),"") | G25: =IF($E25="",0,$F25*$D25)
A26: 2/1 | B26: ECO2122 | C26: ทฤษฎีมหภาค 1 | D26: 3 | F26: =IFERROR(VLOOKUP($E26,Scale!$A$2:$B$9,2,FALSE),"") | G26: =IF($E26="",0,$F26*$D26)
A27: 2/1 | B27: ECO2125 | C27: คณิตศาสตร์สำหรับเศรษฐศาสตร์ | D27: 3 | F27: =IFERROR(VLOOKUP($E27,Scale!$A$2:$B$9,2,FALSE),"") | G27: =IF($E27="",0,$F27*$D27)
A28: 2/1 | B28: ECO2129 | C28: เศรษฐกิจประเทศไทย | D28: 3 | F28: =IFERROR(VLOOKUP($E28,Scale!$A$2:$B$9,2,FALSE),"") | G28: =IF($E28="",0,$F28*$D28)
... A70: 4/2 | B70: STA4309 | C70: Statistical Forecasting Methods | D70: 3 | F70: =IFERROR(VLOOKUP($E70,Scale!$A$2:$B$9,2,FALSE),"") | G70: =IF($E70="",0,$F70*$D70)
F71: =IFERROR(VLOOKUP($E71,Scale!$A$2:$B$9,2,FALSE),"") | G71: =IF($E71="",0,$F71*$D71)
F72: =IFERROR(VLOOKUP($E72,Scale!$A$2:$B$9,2,FALSE),"") | G72: =IF($E72="",0,$F72*$D72)
F73: =IFERROR(VLOOKUP($E73,Scale!$A$2:$B$9,2,FALSE),"") | G73: =IF($E73="",0,$F73*$D73)
F74: =IFERROR(VLOOKUP($E74,Scale!$A$2:$B$9,2,FALSE),"") | G74: =IF($E74="",0,$F74*$D74)
F75: =IFERROR(VLOOKUP($E75,Scale!$A$2:$B$9,2,FALSE),"") | G75: =IF($E75="",0,$F75*$D75)
C76: รวม | D76: =SUM($D$10:$D$75) | G76: =SUM($G$10:$G$75)

Sheet เทียบ ป.โท Top-U
A1: เทียบเกณฑ์ GPAX กับการยื่น ป.โท Top-20 (QS) — โอกาส & ความเสี่ยง
A2: US ขั้นต่ำ ~3.0 (แข่งขัน 3.5–3.7) • elite quant avg ~3.7–3.8 (MIT MFin 3.7) • UK: 2:1≈3.3–3.6, First≈3.7–4.0 (LSE: 3.5=2:1; Oxford First=3.7)
A4: ① เกียรตินิยม → โอกาสยื่น Top-20 (แกน GPA)
A5: เกียรตินิยม | B5: GPAX | C5: เทียบ UK/US | D5: โอกาส Top-20 | E5: ความเสี่ยง
A6: เหรียญทอง | B6: ≥3.80 | C6: First (เกิน) | D6: แข่งได้แทบทุกที่ | E6: 🟢 ต่ำ
A7: อันดับ 1 | B7: 3.60–3.79 | C7: First/high 2:1 | D7: ดี–กลาง (Top-5 กลางๆ) | E7: 🟡 กลาง
A8: อันดับ 2 | B8: 3.30–3.59 | C8: 2:1 (ผ่าน min) | D8: ต่ำกว่าค่าเฉลี่ยที่รับ | E8: 🟠 สูง
A9: (ต่ำกว่า) | B9: <3.30 | C9: ต่ำกว่า 2:1 | D9: ต่ำกว่าขั้นต่ำหลายที่ | E9: 🔴 สูงมาก
A11: ② ปัจจัยสำคัญกว่า GPAX
A12: • ม.ราม = non-target → GPA อ่านตามบริบทสถาบัน → ต้องทำ GPAX สูงกว่าค่าเฉลี่ยเพื่อชดเชย
A13: • ตัวขยับผลจริง: GRE Quant 168–170 • เกรด A วิชาสัญญาณ (Real Analysis/Probability/Theory of Stats/Econometrics) • research/writing sample • LoR • predoc/RA
A14: • GPAX สูง = 'จำเป็นแต่ไม่พอ' — ผ่านด่านคัดกรอง แต่ต้องมีแพ็กเกจครบจึงชนะ target school
A16: ③ สรุปความเสี่ยง (รวม brand ม.ราม)
A17: เหรียญทอง (≥3.80): Top-20 แข่งได้จริง • Top-5 เอื้อมได้ถ้าโปรไฟล์เต็ม
A18: อันดับ 1 (3.60–3.79): Top-20 ดี • Top-5 เสี่ยง ต้องชดเชยหนัก
A19: อันดับ 2 (3.30–3.59): Top-20 เสี่ยงสูง • เล็งอันดับท้าย + ชดเชย GRE/research มาก
A21: แหล่ง: research.com • LSE • Oxford • QuantNet/MIT MFin • เกณฑ์เปลี่ยนได้ ตรวจหน้าโปรแกรมก่อนสมัคร

Sheet Scale
A1: เกรด | B1: แต้ม
A2: A | B2: 4
A3: B+ | B3: 3.5
A4: B | B4: 3
A5: C+ | B5: 2.5
A6: C | B6: 2
A7: D+ | B7: 1.5
A8: D | B8: 1
A9: F | B9: 0
