Workbook

Sheet แผนเรียน v10
A1: แผนการเรียน ป.ตรี เศรษฐศาสตร์ ม.รามคำแหง — Quant+Finance/IB (v12 รวม GPAX — แก้บุพวิชา)
A2: v12: แก้ MTH3611 PR=STA2003 (เดิมใส่ผิด) • ตัด C++ (COS2102) ออก • เพิ่ม STA2003 (แก้ทั้ง ECO2126 & MTH3611) • คง 168 นก./8 เทอม | ชีต GPAX=คำนวณเกรด, ชีต เทียบ ป.โท Top-U=โอกาสเรียนต่อ
A4: ✅ | B4: รหัส | C4: ชื่อวิชา | D4: นก. | E4: ยาก/10 | F4: หมวด / เหตุผล | G4: บุพวิชา | H4: สถานะ / หมายเหตุ
A5: ปีที่ 1 / เทอม 1 (ยากเฉลี่ย 3.1/10) | H5: 21 นก.
B6: ECO1121 | C6: หลักเศรษฐศาสตร์จุลภาค | D6: 3 | E6: 3 | F6: แกน econ | G6: - | H6: ✓
B7: ECO1123 | C7: คณิต–สถิติเบื้องต้นสำหรับ ศ. | D7: 3 | E7: 4 | F7: แกน • ด่านทดสอบเลข | G7: - | H7: ✓
B8: ACC1103 | C8: การบัญชีการเงิน | D8: 3 | E8: 4 | F8: แกน econ | G8: - | H8: ✓
B9: MTH1101 | C9: Calculus & Analytic Geometry I | D9: 3 | E9: 4 | F9: เลือกเสรี | G9: - | H9: ✓
B10: RAM1111 | C10: English in Daily Life | D10: 3 | E10: 2 | F10: ศึกษาทั่วไป 1.1 | G10: - | H10: ✓
B11: RAM1103 | C11: Thai for Communication at Work | D11: 3 | E11: 2 | F11: ศึกษาทั่วไป 1.1 | G11: - | H11: ✓
B12: COS1101 | C12: Introduction to Computer Science | D12: 3 | E12: 3 | F12: เก็บเพิ่ม • พื้นฐาน CS | G12: - | H12: ✓
A13: ปีที่ 1 / เทอม 2 (ยากเฉลี่ย 4.1/10) | H13: 21 นก.
B14: ECO1122 | C14: หลักเศรษฐศาสตร์มหภาค | D14: 3 | E14: 3 | F14: แกน econ | G14: ECO1123 | H14: ✓
B15: MTH1102 | C15: Calculus & Analytic Geometry II | D15: 3 | E15: 5 | F15: เลือกเสรี | G15: MTH1101 | H15: ✓
B16: MTH2001 | C16: Fundamental Concepts in Math 1 | D16: 3 | E16: 7 | F16: ★ พิสูจน์ (ฐาน Real Analysis) | G16: - | H16: ✓
B17: MTH2206 | C17: Matrix Theory & Linear Algebra 1 | D17: 3 | E17: 5 | F17: โทคณิต | G17: MTH1101 | H17: ✓
B18: RAM1131 | C18: Digital Literacy | D18: 3 | E18: 2 | F18: ศึกษาทั่วไป 1.1 | G18: - | H18: ✓
B19: RAM1301 | C19: คุณธรรมคู่ความรู้ | D19: 3 | E19: 2 | F19: ศึกษาทั่วไป 1.3 | G19: - | H19: ✓
B20: COS1103 | C20: Algorithms and Programming | D20: 3 | E20: 5 | F20: เก็บเพิ่ม • Algorithms (พื้นฐาน coding) | G20: COS1101 | H20: ✓ (CR COS1101)
A21: ปีที่ 2 / เทอม 1 (ยากเฉลี่ย 5.6/10) | H21: 21 นก.
B22: ECO2121 | C22: ทฤษฎีจุลภาค 1 | D22: 3 | E22: 6 | F22: แกน econ | G22: ECO1121,1123 | H22: ✓
B23: ECO2122 | C23: ทฤษฎีมหภาค 1 | D23: 3 | E23: 6 | F23: แกน econ | G23: ECO1122,1123 | H23: ✓
B24: ECO2125 | C24: คณิตศาสตร์สำหรับเศรษฐศาสตร์ | D24: 3 | E24: 6 | F24: แกน • วิชาสัญญาณ | G24: ECO1123 | H24: ✓
B25: ECO2129 | C25: เศรษฐกิจประเทศไทย | D25: 3 | E25: 3 | F25: แกน econ | G25: ECO1121,1122 | H25: ✓
B26: MTH2103 | C26: Calculus & Analytic Geometry III | D26: 3 | E26: 6 | F26: โทคณิต • หลายตัวแปร | G26: MTH1102 | H26: ✓
B27: STA3101 | C27: Probability Theory 1 | D27: 3 | E27: 7 | F27: ★ ฐานความน่าจะเป็น | G27: MTH1102 | H27: ✓
B28: STA2003 | C28: Principles of Statistics | D28: 3 | E28: 5 | F28: ★ เพิ่ม v12 • บุพวิชาของ ECO2126 & MTH3611 | G28: - | H28: ✓ (ไม่มีบุพวิชา)
A29: ปีที่ 2 / เทอม 2 (ยากเฉลี่ย 6.1/10) | H29: 21 นก.
B30: ECO2123 | C30: ทฤษฎีจุลภาค 2 | D30: 3 | E30: 7 | F30: แกน econ | G30: ECO2121 | H30: ✓
B31: ECO2124 | C31: ทฤษฎีมหภาค 2 | D31: 3 | E31: 7 | F31: แกน econ | G31: ECO2122 | H31: ✓
B32: ECO2126 | C32: สถิติสำหรับเศรษฐศาสตร์ | D32: 3 | E32: 6 | F32: แกน • วิชาสัญญาณ | G32: STA2003 | H32: ✓ STA2003 อยู่ปี2/เทอม1
B33: MTH2104 | C33: Advanced Calculus 1 | D33: 3 | E33: 8 | F33: โทคณิต • ปลดล็อก Real Analysis | G33: MTH2103 | H33: ✓
B34: MTH3204 | C34: Matrix Theory & Linear Algebra 2 | D34: 3 | E34: 7 | F34: โทคณิต | G34: MTH2206 | H34: ✓
B35: RAM1141 | C35: ศาสตร์แห่งบุคลิกภาพ | D35: 3 | E35: 2 | F35: ศึกษาทั่วไป 1.1 | G35: - | H35: ✓
B36: ACC2202 | C36: Intermediate Accounting | D36: 3 | E36: 6 | F36: บัญชีเชิงลึก (ก่อนฝึกงาน) | G36: ACC1103 | H36: ⚠️ เช็ก ACC1101/1103
A37: ปีที่ 3 / เทอม 1 (ยากเฉลี่ย 6.0/10) | H37: 21 นก.
B38: ECO3121 | C38: เศรษฐศาสตร์จุลภาคระดับสูง | D38: 3 | E38: 8 | F38: เชี่ยวชาญ | G38: ECO2123,2125 | H38: ✓
B39: ECO3123 | C39: เศรษฐมิติเบื้องต้น | D39: 3 | E39: 7 | F39: เชี่ยวชาญ • ดาวเด่น | G39: ECO2125,2126 | H39: ✓ (รอ ECO2126)
B40: ECO3320 | C40: เศรษฐศาสตร์การเงินและการธนาคาร | D40: 3 | E40: 5 | F40: เลือกกลุ่มอื่น–การเงิน | G40: ECO2124 | H40: ✓
B41: MTH2106 | C41: Differential Equations | D41: 3 | E41: 6 | F41: โทคณิต | G41: MTH1102 | H41: ✓
...

Sheet GPAX
A1: 🎓 คำนวณ GPAX อัตโนมัติ — เลือกเกรดในช่องสีเหลือง
A2: A=4.0 B+=3.5 B=3.0 C+=2.5 C=2.0 D+=1.5 D=1.0 F=0.0 • GPAX=Σ(แต้ม×นก.)÷Σนก.ที่มีเกรด (F นับ 0 แต่รวมหน่วยกิต)
A4: 📊 สรุปผล (คำนวณอัตโนมัติ) | I4: GPA รายเทอม
A5: GPAX สะสม | C5: =IF($G$5=0,"",SUM($G$10:$G$70)/$G$5) | E5: หน่วยกิตที่มีเกรดแล้ว | G5: =SUMPRODUCT(($E$10:$E$70<>"")*$D$10:$D$70) | I5: เทอม | J5: GPA | K5: นก.
A6: เทียบเกียรตินิยม* | C6: =IF($C$5="","-",IF($C$5>=3.8,"อันดับ 1 เหรียญทอง 🥇",IF($C$5>=3.6,"อันดับ 1 🏆",IF($C$5>=3.3,"อันดับ 2 🥈","ไม่เข้าเกณฑ์")))) | E6: หน่วยกิตรวมทั้งหมด | G6: =SUM($D$10:$D$70) | I6: 1/1 | J6: =IF(SUMPRODUCT(($A$10:$A$70=$I6)*($E$10:$E$70<>"")*$D$10:$D$70)=0,"",SUMPRODUCT(($A$10:$A$70=$I6)*$G$10:$G$70)/SUMPRODUCT(($A$10:$A$70=$I6)*($E$10:$E$70<>"")*$D$10:$D$70)) | K6: =SUMPRODUCT(($A$10:$A$70=$I6)*($E$10:$E$70<>"")*$D$10:$D$70)
A7: 🎯 ตั้งเป้า GPAX (กรอก) | C7: 3.8 | E7: ต้องได้เฉลี่ยอีก (เต็ม 4) | G7: =IF(($G$6-$G$5)<=0,"-",IF($C$7="","",($C$7*$G$6-SUM($G$10:$G$70))/($G$6-$G$5))) | I7: 1/2 | J7: =IF(SUMPRODUCT(($A$10:$A$70=$I7)*($E$10:$E$70<>"")*$D$10:$D$70)=0,"",SUMPRODUCT(($A$10:$A$70=$I7)*$G$10:$G$70)/SUMPRODUCT(($A$10:$A$70=$I7)*($E$10:$E$70<>"")*$D$10:$D$70)) | K7: =SUMPRODUCT(($A$10:$A$70=$I7)*($E$10:$E$70<>"")*$D$10:$D$70)
A8: เกณฑ์เกียรตินิยม: เหรียญทอง ≥3.80 | อันดับ1 = 3.60–3.79 | อันดับ2 = 3.30–3.59 (ต่ำกว่า 3.30 = ไม่เข้าเกณฑ์) • ดูชีต 'เทียบ ป.โท Top-U' ประกอบ | I8: 2/1 | J8: =IF(SUMPRODUCT(($A$10:$A$70=$I8)*($E$10:$E$70<>"")*$D$10:$D$70)=0,"",SUMPRODUCT(($A$10:$A$70=$I8)*$G$10:$G$70)/SUMPRODUCT(($A$10:$A$70=$I8)*($E$10:$E$70<>"")*$D$10:$D$70)) | K8: =SUMPRODUCT(($A$10:$A$70=$I8)*($E$10:$E$70<>"")*$D$10:$D$70)
A9: ปี/เทอม | B9: รหัส | C9: ชื่อวิชา | D9: นก. | E9: เกรด | F9: แต้ม | G9: แต้ม×นก. | I9: 2/2 | J9: =IF(SUMPRODUCT(($A$10:$A$70=$I9)*($E$10:$E$70<>"")*$D$10:$D$70)=0,"",SUMPRODUCT(($A$10:$A$70=$I9)*$G$10:$G$70)/SUMPRODUCT(($A$10:$A$70=$I9)*($E$10:$E$70<>"")*$D$10:$D$70)) | K9: =SUMPRODUCT(($A$10:$A$70=$I9)*($E$10:$E$70<>"")*$D$10:$D$70)
A10: 1/1 | B10: ECO1121 | C10: หลักเศรษฐศาสตร์จุลภาค | D10: 3 | F10: =IFERROR(VLOOKUP($E10,Scale!$A$2:$B$9,2,FALSE),"") | G10: =IF($E10="",0,$F10*$D10) | I10: 3/1 | J10: =IF(SUMPRODUCT(($A$10:$A$70=$I10)*($E$10:$E$70<>"")*$D$10:$D$70)=0,"",SUMPRODUCT(($A$10:$A$70=$I10)*$G$10:$G$70)/SUMPRODUCT(($A$10:$A$70=$I10)*($E$10:$E$70<>"")*$D$10:$D$70)) | K10: =SUMPRODUCT(($A$10:$A$70=$I10)*($E$10:$E$70<>"")*$D$10:$D$70)
A11: 1/1 | B11: ECO1123 | C11: คณิต–สถิติเบื้องต้นสำหรับ ศ. | D11: 3 | F11: =IFERROR(VLOOKUP($E11,Scale!$A$2:$B$9,2,FALSE),"") | G11: =IF($E11="",0,$F11*$D11) | I11: 3/2 | J11: =IF(SUMPRODUCT(($A$10:$A$70=$I11)*($E$10:$E$70<>"")*$D$10:$D$70)=0,"",SUMPRODUCT(($A$10:$A$70=$I11)*$G$10:$G$70)/SUMPRODUCT(($A$10:$A$70=$I11)*($E$10:$E$70<>"")*$D$10:$D$70)) | K11: =SUMPRODUCT(($A$10:$A$70=$I11)*($E$10:$E$70<>"")*$D$10:$D$70)
A12: 1/1 | B12: ACC1103 | C12: การบัญชีการเงิน | D12: 3 | F12: =IFERROR(VLOOKUP($E12,Scale!$A$2:$B$9,2,FALSE),"") | G12: =IF($E12="",0,$F12*$D12) | I12: 4/1 | J12: =IF(SUMPRODUCT(($A$10:$A$70=$I12)*($E$10:$E$70<>"")*$D$10:$D$70)=0,"",SUMPRODUCT(($A$10:$A$70=$I12)*$G$10:$G$70)/SUMPRODUCT(($A$10:$A$70=$I12)*($E$10:$E$70<>"")*$D$10:$D$70)) | K12: =SUMPRODUCT(($A$10:$A$70=$I12)*($E$10:$E$70<>"")*$D$10:$D$70)
A13: 1/1 | B13: MTH1101 | C13: Calculus & Analytic Geometry I | D13: 3 | F13: =IFERROR(VLOOKUP($E13,Scale!$A$2:$B$9,2,FALSE),"") | G13: =IF($E13="",0,$F13*$D13) | I13: 4/2 | J13: =IF(SUMPRODUCT(($A$10:$A$70=$I13)*($E$10:$E$70<>"")*$D$10:$D$70)=0,"",SUMPRODUCT(($A$10:$A$70=$I13)*$G$10:$G$70)/SUMPRODUCT(($A$10:$A$70=$I13)*($E$10:$E$70<>"")*$D$10:$D$70)) | K13: =SUMPRODUCT(($A$10:$A$70=$I13)*($E$10:$E$70<>"")*$D$10:$D$70)
A14: 1/1 | B14: RAM1111 | C14: English in Daily Life | D14: 3 | F14: =IFERROR(VLOOKUP($E14,Scale!$A$2:$B$9,2,FALSE),"") | G14: =IF($E14="",0,$F14*$D14)
A15: 1/1 | B15: RAM1103 | C15: Thai for Communication at Work | D15: 3 | F15: =IFERROR(VLOOKUP($E15,Scale!$A$2:$B$9,2,FALSE),"") | G15: =IF($E15="",0,$F15*$D15)
A16: 1/1 | B16: COS1101 | C16: Introduction to Computer Science | D16: 3 | F16: =IFERROR(VLOOKUP($E16,Scale!$A$2:$B$9,2,FALSE),"") | G16: =IF($E16="",0,$F16*$D16)
A17: 1/2 | B17: ECO1122 | C17: หลักเศรษฐศาสตร์มหภาค | D17: 3 | F17: =IFERROR(VLOOKUP($E17,Scale!$A$2:$B$9,2,FALSE),"") | G17: =IF($E17="",0,$F17*$D17)
A18: 1/2 | B18: MTH1102 | C18: Calculus & Analytic Geometry II | D18: 3 | F18: =IFERROR(VLOOKUP($E18,Scale!$A$2:$B$9,2,FALSE),"") | G18: =IF($E18="",0,$F18*$D18)
A19: 1/2 | B19: MTH2001 | C19: Fundamental Concepts in Math 1 | D19: 3 | F19: =IFERROR(VLOOKUP($E19,Scale!$A$2:$B$9,2,FALSE),"") | G19: =IF($E19="",0,$F19*$D19)
A20: 1/2 | B20: MTH2206 | C20: Matrix Theory & Linear Algebra 1 | D20: 3 | F20: =IFERROR(VLOOKUP($E20,Scale!$A$2:$B$9,2,FALSE),"") | G20: =IF($E20="",0,$F20*$D20)
A21: 1/2 | B21: RAM1131 | C21: Digital Literacy | D21: 3 | F21: =IFERROR(VLOOKUP($E21,Scale!$A$2:$B$9,2,FALSE),"") | G21: =IF($E21="",0,$F21*$D21)
A22: 1/2 | B22: RAM1301 | C22: คุณธรรมคู่ความรู้ | D22: 3 | F22: =IFERROR(VLOOKUP($E22,Scale!$A$2:$B$9,2,FALSE),"") | G22: =IF($E22="",0,$F22*$D22)
A23: 1/2 | B23: COS1103 | C23: Algorithms and Programming | D23: 3 | F23: =IFERROR(VLOOKUP($E23,Scale!$A$2:$B$9,2,FALSE),"") | G23: =IF($E23="",0,$F23*$D23)
A24: 2/1 | B24: ECO2121 | C24: ทฤษฎีจุลภาค 1 | D24: 3 | F24: =IFERROR(VLOOKUP($E24,Scale!$A$2:$B$9,2,FALSE),"") | G24: =IF($E24="",0,$F24*$D24)
A25: 2/1 | B25: ECO2122 | C25: ทฤษฎีมหภาค 1 | D25: 3 | F25: =IFERROR(VLOOKUP($E25,Scale!$A$2:$B$9,2,FALSE),"") | G25: =IF($E25="",0,$F25*$D25)
... A65: 4/2 | B65: STA4101 | C65: Theory of Statistics 1 | D65: 3 | F65: =IFERROR(VLOOKUP($E65,Scale!$A$2:$B$9,2,FALSE),"") | G65: =IF($E65="",0,$F65*$D65)
F66: =IFERROR(VLOOKUP($E66,Scale!$A$2:$B$9,2,FALSE),"") | G66: =IF($E66="",0,$F66*$D66)
F67: =IFERROR(VLOOKUP($E67,Scale!$A$2:$B$9,2,FALSE),"") | G67: =IF($E67="",0,$F67*$D67)
F68: =IFERROR(VLOOKUP($E68,Scale!$A$2:$B$9,2,FALSE),"") | G68: =IF($E68="",0,$F68*$D68)
F69: =IFERROR(VLOOKUP($E69,Scale!$A$2:$B$9,2,FALSE),"") | G69: =IF($E69="",0,$F69*$D69)
F70: =IFERROR(VLOOKUP($E70,Scale!$A$2:$B$9,2,FALSE),"") | G70: =IF($E70="",0,$F70*$D70)
C71: รวม | D71: =SUM($D$10:$D$70) | G71: =SUM($G$10:$G$70)

Sheet เทียบ ป.โท Top-U
A1: เทียบเกณฑ์ GPAX กับการยื่น ป.โท Top-20 (QS) — โอกาส & ความเสี่ยง
A2: อ้างอิงเกณฑ์รับเข้าทั่วไป (2026): US ป.โทส่วนใหญ่ขั้นต่ำ 3.0 (70% ขอ 3.0–3.5) แข่งขัน 3.5–3.7 • elite quant ค่าเฉลี่ยที่รับ ~3.7–3.8 (MIT MFin 3.7) • UK: 2:1 ≈ GPA 3.3–3.6, First ≈ 3.7–4.0 (LSE: 3.5=2:1; Oxford strong-2:1=3.5, First=3.7) • LSE/Oxford ที่รับจริงส่วนใหญ่ได้ First
A4: ① แมปเกณฑ์เกียรตินิยมของคุณ → โอกาสยื่น Top-20 (แกน GPA)
A5: เกียรตินิยม | B5: GPAX | C5: เทียบ UK/US | D5: โอกาส Top-20 (เชิง GPA) | E5: ความเสี่ยง
A6: เหรียญทอง | B6: ≥ 3.80 | C6: First (เกิน) • เกิน MIT MFin avg | D6: แข่งขันได้แทบทุกโปรแกรม Top-20 | E6: 🟢 ต่ำ
A7: อันดับ 1 | B7: 3.60–3.79 | C7: First / high 2:1 • 3.7=avg MIT MFin | D7: แข่งได้ดี-กลาง (Top-5 = กลางๆ) | E7: 🟡 กลาง
A8: อันดับ 2 | B8: 3.30–3.59 | C8: 2:1 (ผ่าน min LSE/Oxford/US) | D8: ผ่านขั้นต่ำ แต่ต่ำกว่าค่าเฉลี่ยที่รับ | E8: 🟠 สูง (โดยเฉพาะ Top-5)
A9: (ต่ำกว่าเกณฑ์) | B9: < 3.30 | C9: ต่ำกว่า 2:1 | D9: ต่ำกว่าขั้นต่ำหลายที่ | E9: 🔴 สูงมาก
A11: ② ⚠️ ปัจจัยที่สำคัญกว่า GPAX (ต้องรู้!)
A12: • ม.รามคำแหง = 'non-target / open university' → adcom อ่าน GPA ตามบริบทสถาบัน → GPAX ต้อง 'สูงกว่าค่าเฉลี่ย' เพื่อชดเชย brand discount
A13: • ตัวชี้วัดที่ขยับผลจริง: ① GRE Quant สูง (168–170) ② เกรด A วิชาสัญญาณ (Real Analysis, Probability, Theory of Stats, Econometrics) ③ research/writing sample ④ จดหมายแนะนำแรง ⑤ ประสบการณ์/predoc/RA
A14: • สรุป: GPAX สูง = 'จำเป็นแต่ไม่พอ' — ผ่านด่านคัดกรอง แต่ต้องมีแพ็กเกจครบจึงชนะคู่แข่งจาก target school
A15: • เคล็ด: ถึง GPAX รวมจะโดน gen-ed ฉุด ให้รักษาเกรดวิชาสัญญาณ (สีเขียวในแผน) ให้ A ไว้ — adcom quant ดูตรงนี้ก่อน GPAX รวม
A17: ③ สรุปความเสี่ยงเชิงปฏิบัติ (เมื่อรวม brand ม.ราม)
A18: เหรียญทอง (≥3.80): Top-20 = แข่งได้จริง (ต้องมี GRE+research+LoR ครบ) • Top-5 (MIT/Stanford/Harvard/LSE) = เอื้อมได้แต่ต้องโปรไฟล์เต็ม
A19: อันดับ 1 (3.60–3.79): Top-20 กลาง-ล่าง = โอกาสดี • Top-5 = เสี่ยง ต้องชดเชยหนักด้วย GRE/research
A20: อันดับ 2 (3.30–3.59): Top-20 = เสี่ยงสูง • ควรเล็ง Top-20 อันดับท้าย + โปรแกรมที่ fit + ชดเชยด้วย GRE/research มาก หรือไต่ผ่าน predoc/ทำงานก่อน
A22: แหล่งอ้างอิง: research.com (Finance/Econ Master's 2026) • LSE MSc Finance & Economics • Oxford International Qualifications • QuantNet/MIT MFin • เกณฑ์เปลี่ยนได้ ตรวจหน้าโปรแกรมจริงก่อนสมัคร

Sheet Scale
A1: เกรด | B1: แต้ม
A2: A | B2: 4
A3: B+ | B3: 3.5
A4: B | B4: 3
A5: C+ | B5: 2.5
A6: C | B6: 2
A7: D+ | B7: 1.5
A8: D | B8: 1
A9: F | B9: 0
